

# 十二. 异步编程之Promise/async/await

# 一、准备

## 1. 区分实例对象与函数对象

* 实例对象：new 关键字产生的对象，成为实例对象，简称对象

```js
function Person () {
    
}
const person1 = new Person(); // 这个peroson1 就是构造函数Person的实例对象
```

* 函数对象：将函数作为对象使用时，简称为函数对象

```js
我们知道一般小括号()左边就是函数
function Person () {
    
}
Person是一个函数
Person.prototype // 对象才可以使用点【.】点的左边是对象 此时Person的角色是对象 这代表Person也是个对象
// 所以Person既是对象也是函数 所以Person是函数对象

所以我们平时叫对象都是实例对象，因为实例对象简称对象。
```



## 2. 两种类型的回调函数

* 同步回调

  * 理解：立即执行，完全执行完了才结束，不会放入回调队列中

  * 例子：数组遍历相关的回调函数，Promise的excutor函数

  * ```js
    回调函数：1. 我自己定义的 2.并且我没有调用 3. 但是最后还是执行了
    const arr = [1, 2, 3];
    arr.forEach(item => {
        console.log(item)
    }) // 遍历回调
    console.log('回调函数后执行')
    
    上面执行打印结果就是 1、3、5 '回调函数后执行' 说明forEach里的回到函数 是同步回调
    ```

    

* 异步回调

  * 理解：不会立即执行，会放到回调队列中执行

  * 例子：定时器回调、ajax回调、Promise成功与失败回调

  * ```js
    setTimeout(() => {
        console.log('setTimeout 回调函数')
    }, 0)
    
    console.log('setTimeout之后执行')
    
    上面执行打印结果就是 'setTimeout之后执行' 'setTimeout 回调函数' 说明setTimeout里的回到函数 是异步回调
    ```



## 3. js里的error处理

* 错误的类型

  * Error: 所有错误的父类型

  * ReferenceError: 引用变量不存在 

    * ```js
      console.log(a) // 打印一个未定义的变量
      ```

  * TypeError：数据类型不正确的错误

    * ```js
      let b = null;
      console.log(b.name); // Uncaught TypeError: Cannot read property 'name' of null
      
      说明要写读取这个属性 必须是一个对象 而你不是对象是null 类型错误
      ```

  * RangeErroe：数据值不允许在其所允许的范围内

    * ```js
      function show () {
          show() // 无限制递归调用
      }
      show()
      // Uncaught RangeError: Maximum call stack size exceeded
      ```

  * SystaxError：语法错误

* 错误处理

  * 捕获错误：try...catch
  
  * ```js
    try {
        let a;
        console.log(a.name)
    } catch(err) {
        console.log(err)
        // TypeError: Cannot read property 'name' of undefined
        // at <anonymous>:3:19
        
        console.log(err.message)
        console.log(err.stack)
    }
    
    console.log(111) // 如果没有对错误进行捕获处理 那么此行代码不会执行 我们上面对错误进行处理了所以 可以执行此行代码
    ```
  
  * 抛出错误：throw error
  
    * 我们自己可以去抛出异常
    * throw.error(message)

# 二、什么是Promise？

## 1. promise是什么？

* 抽象表达
  promise是js进行异步编程新的解决方案
* 具体表达
  * 从语法上来说Promise是一个构造函数
  * 从功能上来说promise对象(这里的对象是实例对象)封装一个异步操作，并可以获取其结果

## 2. promise相比旧的方案的好处?
* 指定回调函数的方式更灵活
* 旧的: 启动`异步任务前`(执行器函数里的异步任务)指定回调函数(then，catch回调函数)
* promise: 启动异步任务，返回promise对象，给promise对象绑定回调函数(甚至可以在异步任务结束后指定回调函数) 数据不会丢掉
* 支持链式调用，链式调用可以解决回调地狱问题。
  * 什么是回调地狱?
    回调函数嵌套调用，外部回调函数异步执行的结果是嵌套的回调函数执行的条件。
  * 回调地狱的特点?
    * 不便于阅读/不便于异常处理
    * 解决方案promise链式调用。
  * 终极解决方案?
    async，await

```js
new Promise((resolve, reject) => {...}) /* executor执行器 立即执行这个函数 这个函数接收两个参数 */

Promise.prototype.then方法: (onResolved,onRejected) => {}
onResolved函数:成功的回调函数(value) => {}
onRejected函数:失败的回调函数(reason) => {}
then()的语法糖，相当于then(undefined, onRejected)
注意：`then方法返回一个新的Promise 且这个Promise 相当于内部new了一个Promise.resolve(params) params就是then方法里面的返回值 默认返回值undefined 可以手动return 返回值`

Promise.prototype.catch方法                                    
onRejected函数:失败的回调函数(reason) => {}

Promise.resolve(2)  产生一个成功的值为2promise对象
Promise.reject(3)  产生一个失败的值为3的promise对象

const pAll = Promise.all([p1, p2, p3]) // p1,p2,p3代表promise对象, pAll是返回一个新的promise对象

const pRace = Promise.race([p1,p2,p3]) // 返回第一个完成请求的promise(race比赛的意思谁先完成返回那个promise，不管请求成功还是失败返回那个第一名)
```



## 3. 如何改变promise状态?

* promise的状态改变
  * resolve(value)如果当前是`pending(即将发生的,在等待，未确定)`变为`resolved`
  * reject(reason)如果当前是`pending(即将发生的,在等待，未确定)`变为`rejected`
  * 只有这两种状态改变，状态改变不可逆，一个promise对象只能改变一次，无论成功与失败，都会有一个结果数据，成功数据一般vulue（或res/result）,失败的结果一般是reason（err）
  * 抛出异常 throw new Error（'出错了'）如果当前是pending就会变成rejected，那么reason就是error，也可以抛3，throw 3

一个Promise可以绑定多个then成功或者失败的回调，可以做不同的事情
.then也是同步任务.then里的函数是异步

## 4. promise.then() 返回的新promise的结果状态由什么决定
* 简单表达: 由then()指定的回调函数执行的结果决定
* 详细表达:
  * 如果抛出异常 新promise变为rejected，reason为抛出的异常如果返回的是非promise的任意值，新promise变为resolved value为返回的值。
  * 如果返回的是另一个新promise，此promise的结果就会变成新promise的结果

* 总结: 就是说，由调用.then的promise对象决定.then指定的回调函数到底执行哪个函数（resolve，reject），.then返回的promise由函数执行的结果来决定。

## 5. promise如何串连多个操作任务?
* promise的`.then()`返回一个新的promise，可以看成then()的链式调用。

* 通过.then的链式调用串连多个同步/异步任务（异步需要return一个promise里）

* ```js
  new Promise((resolve, reject) => {
      resolve(1)
  })
  .then(res => {
      return 1
      console.log(res)
  })
  .then(res => {
      Promise.resolve(3)
      console.log(res)
  })
  .catch(err => {
      console.log(err)
  })
  ```

## 6. 什么是promise异常传透?
* 当使用promise`.then`链式调用时，可以在最后指定失败的回调。

* 前面任何操作出了异常，都会传到最后失败的回调中，处理未写的失败的回调函数（onRejected）相当于默认写了  reason => { throw reason }括号不能去，去了相当于return throw reason

* ```js
  
  // 失败的回调 他会一直向下查找 是否有 处理异常的回调
  new Promise((resolve, reject) => {
      reject(1)
  })
  .then(res => {
      Promise.resolve(2)
  })
  .then(res => {
      return 3
  })
  .catch(err => {
      console.log(err)
  })
  // 大家会有个疑问 为什么会一直向下传递呢
  // 正常情况下 如果某一个.then里写了处理 异常的回调函数，那么就不会继续往下传
  // 其实如果不写then的第二个参数，也就是onRejected 内部会自动处理的，相当于下面
  // 依次向下逐级传递
  new Promise((resolve, reject) => {
      reject(1)
  })
  .then(res => {
     return res
  },
        err => { throw err })
  .then(res => {
      Promise.reject(res)
  },
      err => { throw err } )
  .catch(err => {
      console.log(err, 'err')
  })
  ```

## 7. 如何中断promise链?
* 当使用promise的then链式调用时，在中间中断，不在调用后面回调函数。

* 方法: 在回调函数中返回一个pending状态的promise对象 return Promise (()=>{})这个就属于处于pending状态的promise

* ```js
  new Promise((resolve, reject) => {
      reject(1)
  })
  .then(res => {
      return 2
  })
  .then(res => {
      resolve(3)
  })
  .catch(err => {
      console.log(err, 'err')
  })
  .then(res => {
     console.log(res)
  })
  // 打印上面代码我们会发现 执行catch里的回调函数之后，还会执行下面的then方法，我们不想这样，我们期待的是，当执行catch里的回调函数之后，不想执行下面的then了，那么该怎么办
  new Promise((resolve, reject) => {
      reject(1)
  })
  .then(res => {
      return 2
  })
  .then(res => {
      resolve(3)
  })
  .catch(err => {
      console.log(err, 'err')
      return new Promise(() => {}) // 我们只需要返回一个pending状态的promise就可以终止
  })
  .then(res => {
     console.log(res)
  })
  ```

* 

# 三、Promise详解

## 1. 图片加载之任务队列【宏任务】

```js
function loadImage(src,resolve,reject) {
    let image = new Image();
    image.src = src;
    image.onload = () => {
        resolve(image)
    };
    image.onerror = reject;
}

// 放入相对路径 要在html文件中运行哦，在控制台会报错找不到图片
loadImage('../image/star.jfif', 
          image => {
    console.log('图片加载完成');
    document.body.appendChild(image);
},
         (err) => {
    console.log('图片加载失败');
    throw new Error(err);
});

console.log('开始执行加载图片函数');


先把这个函数交给文件处理模块，等处理完，再放到任务队列中，主线程代码（从上到下执行完代码后），再去任务队列执行任务，不断地轮询
所以说先打印的【开始执行加载图片函数】在打印图片加载成功或失败

# 执行顺序在定时器前面
```



## 2. 定时器之任务队列【宏任务】

```js
js有专门处理定时器的模块（定时器管理模块），先执行主线程任务，如果遇到定时器任务，放入专门处理定时器任务的模块，等定时器时间到了，再放入任务队列中，等到主线程任务执行完之后，再去任务队列里面找轮询执行任务,在此期间如果定时器设置500ms之后执行，但是主线程执行代码时间超过500ms，这时候定时器任务会被放入到任务队列（把console.log(1)放到任务对立里），那么也要等主线程执行完毕之后，才会去轮询任务队列

let code = setInterval(() => console.log(1), 500);
console.time('z');
console.log('先执行主线程');
console.timeEnd('z');
// 执行顺序是先执行主线程代码

console.log('先执行主线程');在执行定时器任务


setInterval(() => console.log('我是后执行的'), 500);
setInterval(() => console.log('我是先执行的'), 100);

如果有多个定时器执行顺序也是，等谁先加载完，谁放入任务队列，如果时间相同那么就看执行的先后顺序

setInterval(() => console.log('我是先执行的'), 100);
setInterval(() => console.log('我是后执行的'), 100);
```



## 3. 文件依赖之任务队列

```js
我们先定义两个js文件内容

第一个js文件内容：
function show() {
    
}

第二个js文件内容：
function run() {
    show(); // 这个函数依赖第一个js文件里的函数
}

// 我们来定义一个加载js文件的函数
function loadScript (src, reslove) {
    let script = document.createElement('script');
    script.src = src;
    script.onload = reslove;
    document.body.appendChild(script);
}
loadScript('./1.js', () => {
    show();
});
loadScript('./2.js', () => {
    run();
});

由于加载js的顺序是不一定的，也就是说，谁加载完毕之后，谁就放入到任务队列中，并不适用代码执行顺序来放入到任务队列中。所有有时候会报错

# 所有我们只能等1.js加载完再去加载2.js
修改如下

loadScript('./1.js', () => {
        show();
        loadScript('./2.js', () => {
        run();
    });
});

这样的弊端就是需要大量的嵌套，如果有其他函数害依赖run函数那么就需要一直嵌套下去，嵌套关系越来越复杂，我们后面会讲到promise会解决这个问题。
```



## 4. ajax请求之任务队列

```js
这里我们暂时无法模拟，但是，ajax请求也是会放到任务队列中，也是需要等待主线程执行完毕，才放入主线程里去执行。
```



## 5. Promise之任务队列【微任务】

```js
// 我们需要使用new 关键字来创建 一个promise 
例如下面这样属于pending 【准备状态】
new Promise((resolve,reject) => {})

但是一个回调必须有成功 或者 失败状态

1. 成功状态 执行resolve()函数
new Promise((resolve,reject) => {
    resolve('成功了'); 
})
Promise {<resolved>: "成功了"} // 由pending 状态 变为 resolved 代表成功状态 

2. 失败状态 reject()函数
new Promise((resolve,reject) => {
    reject('失败了'); // 执行resolve()函数代表成功
})

Promise {<rejected>: "失败了"} // 由pending 状态 变为 rejected 代表失败状态


3. 当状态由pending状态 变为 成功或者失败的状态 的时候执行成功或失败的回调
第一种方法是使用.then()回调函数。.then(resolve,reject)接收两个参数第一个是resolve成功的回调函数，第二个是reject失败的回调函数
new Promise((resolve,reject) => {
    reject('失败了'); // 执行resolve()函数代表成功
})
    .then(() => {
    console.log('成功的回调函数')
},  () => {
    console.log('失败的回调函数')
})

4. 我们可以不写.then的第二个参数，直接改为.catch这样就是.then只处理成功的回到函数，.catch只处理失败的回调函数这样分工明确看着不累
new Promise((resolve,reject) => {
    reject('失败了'); // 执行resolve()函数代表成功
})
    .then(() => {
    console.log('成功的回调函数')
})
    .catch(() => {
    console.log('失败的回调函数')
})

也是当执行到Promise的时候放入到任务队列，任务队列分两种一种是微任务队列，一种是宏任务队列，Promise属于微任务队列，微任务会先执行，宏任务会后执行
```



## 6. 宏任务与微任务执行顺序

```js
# 先执行同步任务 在执行异步任务 异步任务分为宏任务和微任务，先执行微任务，在执行宏任务

1.在Promise构造函数中的代码是同步执行的
new Promise(() => {
    console.log(1);
})
.then(() => {
    console.log(3); // 注意这里是不会执行的 因为他必须要等到一个成功的通知 才会执行 这时候是没有通知的所以不会执行
})
console.log(2);

// 输出内容为 1 2
// () => { console.log(1)} 这个函数是执行器函数 在这函数里执行异步任务

2.
new Promise(resolve => {
    console.log(1);
    resolve('成功了');
})
.then(res => {
    console.log(res); // 这时候我们得到了一个成功的通知我们会把这个任务【.then()这个任务】放到任务队列的微任务中
})
console.log(2);

// 输出内容为  1 2 '成功了'

3.
setTimeout(() => console.log('setTimeout'), 1000)
new Promise(resolve => {
    console.log(1);
    resolve('成功了');
})
.then(res => {
    console.log(res); // 这时候我们得到了一个成功的通知我们会把这个任务【.then()这个任务】放到任务队列的微任务中
})
console.log(2);

// 输出内容为  1 2 '成功了' 'setTimeout'


4. 
new Promise(resolve => {
    console.log(1);
    setTimeout(() => {
        console.log('setTimeout'); // 这两行代码顺序调换其实输出结果是一样的，没有影响
        resolve('成功了'); // 这两行代码顺序调换其实输出结果是一样的，没有影响
    }, 1000)
})
.then(res => {
    console.log(res);
})
console.log(2);

上面是先执行定时器的宏任务才发现微任务，此时的定时器宏任务已经拿到主线程去执行了，就算遇到微任务，会先放到微任务中，等待主线程执行完毕在去轮询任务队列。

// 输出内容为  1 2 'setTimeout' '成功了' 
```



## 7. Promise状态不可更改

```js
1.
new Promise((resolve,reject) => {
    resolve('成功了'); // 由pending变更为resolved状态
    reject('失败了'); // 再次改变状态是不生效的 不可以更改的
})
.then(res => {
    console.log(res);
})
.catch(err => {
    console.log(err);
})


2. resolve,reject传递promise

1. 成功的状态
const promise1 = new Promise((resolve,reject) => {
    resolve('成功了');
});
// 其实返回的成功的状态

2.失败的状态
const promise2 = new Promise((resolve,reject) => {
    reject('失败了');
});

3. 准备的状态
const promise3 = new Promise((resolve,reject) => {
    
});
new Promise((resolve,reject) => {
   // resolve(promise1); // 其实传递的是一个promise的状态
   // reject(promise2);  // 其实传递的是一个promise的状态
   // resolve(promise3);
    resolve(promise2); // 用成功的状态传递一个失败的状态 那么由传递的状态为主
})
.then(res => {
    console.log(res);
})
.catch(err => {
    console.log(err);
})
```



## 8. Promise.then（onResolved）

```js
on 当...时候 一般有on 基本上是回调函数
1.new Promise((resolve,reject) => {
    resolve('1');
})
    .then( res => console.log(res), err => {})

2. 不需要成功的回调传入一个null就行了
new Promise((resolve,reject) => {
    reject('err');
})
    .then(null, err => console.log(err));

3. 多个then 如果上个then返回状态为resolved 会接着执行下面的then 如果返回 rejected会执行catch
new Promise((resolve,reject) => {
    resolve('1')
})
    .then()
    .then(res => console.log(res));

4.
new Promise((resolve,reject) => {
    resolve('1')
})
    .then()
    .then(res => console.log(res))
    .then(res => console.log('111'))


5.Promise.then也是一个Promise
let p1 = new Promise((resolve,reject) => {
    resolve('1')
})
console.log(p1); // Promise {<resolved>: "1"} resloved状态
let p2 = p1.then()
console.log(p2); // Promise {<pending>} pending状态
先执行同步 在去任务队列轮询

6.
new Promise((resolve,reject) => {
    reject('1');
})
    .then(null, err => {
    console.log(err)
    return 2;
}) // 别看他是reject 但是执行完之后的状态还是resolved是成功的,所以还是会执行 下个then()方法
    .then(res => console.log(res));

如果then里面return 一个普通值 会传入下一个then里面，这时候状态会变为resolved，如果返回的是一个promise那么会传递这个promise的状态到下一个then/catch中，如果是pending状态则不会传递到，注意必须【return】一个promise才行，下一个then才是对这个return的promise状态进行处理，要不然不会对这个promise进行处理,后面的then就是对前面返回的promise状态进行处理

7. return 一个promise
new Promise((resolve,reject) => {
    resolve('1');
})
    .then(res => {
    return new Promise((resolve,reject) => {
        resolve('return promise')
    })
})
    .then(res => console.log(res));

// return promise

8. 不return一个promise
new Promise((resolve,reject) => {
    resolve('1');
})
    .then(res => {
    new Promise((resolve,reject) => {
        resolve('return promise')
    })
})
    .then(res => console.log(res));

// undefined


9. // 模拟 我们需要一个接口返回来的数据 去请求另一个接口 
ajax()
    .then(res=>{
     return ajax2(res.userId);
})
    .then((res) => {
    console.log(res, '数据')
})
```



## 9. Promise.catch（onRejected）

```js
用来捕获失败状态的回调
1.
new Promise((resolve,reject) => {
    reject('失败了');
})
    .then(null,err => {
    console.log(err)
})


2.上面写法，then的第二个参数，可以简写下面这样
new Promise((resolve,reject) => {
    reject('失败了');
})
    .catch(err => {
    console.log(err)
})

3.多个catch
new Promise((resolve,reject) => {
    reject('失败了');
})
    .then(res => { console.log(res), err => console.log(err, 'then里面的回调'))
    .catch(err => {
    console.log(err);
})
    .then(() => console.log('catch执行完后执行'))

// 失败了 then里面的回调 catch执行完后执行
                  
会执行第一个catch 如果catch里面没有在抛出rejected的状态 那么状态会变为resolved状态
```



## 10. Promise.finally

```js
无论是成功状态还是失败状态都会执行，一般用于完成关闭loading加载
new Promise((resolve,reject) => {
    // reject('失败了');
    resolve('成功了');
})
    .then(res => {
    console.log(res)
})
    .catch(err => {
    console.log(err)
})
    .finally(() => {
    console.log('执行完毕,永远会执行');
})

```



## 11. Promise封装setTimeout定时器

```js
function timeout(delay = 1000) {
    return new Promise(resolve => {
        console.log(resolve)
        setTimeout(resolve,delay);
    })
}

timeout(2000).then(() => console.log(1));
```



## 12.  构建扁平化的setInterval

```js
function interval(delay = 1000, callback) {
    return new Promise((resolve,reject) => {
        let timerCode = setInterval(() => {
            callback(timerCode, resolve)
        },delay)
    })
}
interval(1000,(timerCode, resolve)=>{
    console.log('循环开始');
    // clearInterval(timerCode);
    resolve('111');
})
    .then((res) => {
    console.log(res);
    console.log('成功了');
})
```



## 13. Promise.resolve()缓存后台数据

```js
new Promise((resolve) => {
    resolve('成功的promise');
}); // 其实就是对这个的简写

Promise.resolve('成功的promise'); // Promise {<resolved>: "成功的promise"}

Promise.resolve('成功的promise').then(res => console.log(res)); // 成功的promise


function getTableData(name) {
    const cache = getTableData.cache || (getTableData.cache = new Map());
    
    if (cache.has(name)) {
        console.log("走缓存了");
        return Promise.resolve(cache.get(name));
     }
   
    return ajax().then( res => {
          cache.set(name, res);
          console.log("没走缓存");
          return res;
     })
    
    setInterval(() => {
        getTableData('a')
    }, 1000);
```



## 14. Promise.reject()

```js
以前的写法：
new Promise((resolve, reject) => {
    reject('失败了');
})
    .catch(err => console.log(err));

简写
Promise.reject('失败了').catch(err => console.log(err));
```



## 15. Promise.all批量获取数据

```js
所有的promise返回成功，才是成功的状态，有一个返回失败就是失败的状态，属于并行完成

1. 全部成功
let p1 = Promise.resolve('成功的promise1');
let p2 = Promise.resolve('成功的promise2');
Promise.all([
    p1,
    p2
])
    .then(res => console.log(res)); // ["成功的promise1", "成功的promise2"]

2. 有一个失败的
let p1 = Promise.resolve('成功的promise1');
let p2 = Promise.reject('失败的promise1');
let p3 = Promise.reject('成功的promise2');
Promise.all([
    p1,
    p2,
    p3
])
    .then(res => console.log(res))
    .catch(err => console.log(err)) // 失败的promise1

3. 多个失败的 返回第一个失败的
let p1 = Promise.resolve('成功的promise1');
let p2 = Promise.reject('失败的promise1');
let p3 = Promise.reject('成功的promise2');
Promise.all([
    p1,
    p2,
    p3
])
    .then(res => console.log(res))
    .catch(err => console.log(err)) // 失败的promise1

```



## 16. Promise.allSettled()使用

```js
// 返回所有状态 不管成功 失败

let p1 = Promise.resolve('成功的promise1');
let p2 = Promise.reject('失败的promise1');
let p3 = Promise.reject('成功的promise2');
Promise.allSettled([
    p1,
    p2,
    p3
])
    .then(res => console.log(res, 'res'));

//  [
// {status: "fulfilled", value: "成功的promise1"},
// {status: "rejected", reason: "失败的promise1"}, 
// {status: "rejected", reason: "成功的promise2"}
// ]

# 成功的返回成功状态 和 请求成功的结果的值，失败的返回失败的原因和失败的值

永远返回是成功的状态也就是说走then

妙用：筛选出成功的 回调

let p1 = Promise.resolve('成功的promise1');
let p2 = Promise.reject('失败的promise1');
let p3 = Promise.reject('成功的promise2');
Promise.allSettled([
    p1,
    p2,
    p3
])
    .then(res => {
    return res.filter(item => item.status === 'fulfilled')
}).then(res => console.log(res, 'res'));
```



## 17. Promise.race后台请求超时处理

```js
批量获取多个Promise,只取返回最快的那个
race： 竞赛
#： 使用
let p1 = Promise.resolve('成功的promise1');
let p2 = Promise.reject('失败的promise1');
let p3 = Promise.reject('成功的promise2');
Promise.race([
    p1,
    p2,
    p3
])
    .then(res => console.log(res))
    .catch(err => console.log(err));


1.实际应用 如果所有请求都超过两秒 那么我们自定义一个请求超时的promise返回去
let p1 = Promise.resolve('成功的promise1');
let p2 = Promise.reject('失败的promise1');
let p3 = Promise.reject('成功的promise2');
let p4 = new Promise(resolve => {
    setTimeout(()=> {
        resolve('请求超时');
    }, 3000)
})
Promise.race([
    p1,
    p2,
    p3,
    p4
])
    .then(res => console.log(res))
    .catch(err => console.log(err));
```



## 18. async函数

* async函数

* 之所以称async函数 是因为async后面接的是一个函数

* async函数的返回值为Promise对象

* Promise对象的结果由async函数执行的结果决定

* ```js
  我们首先定义一个函数 getName， 毫无疑问返回值是字符串 '法外狂徒张三'
  function getName () {
      return '法外狂徒张三'
  }
  console.log(getName());
  
  我们使用async在定义一个函数 返回值将是一个Promise对象 具体是resolved，还是rejected 由函数执行结果来决定 很明显下面是resolved
  async function getAge () {
      return 18
  }
  console.log(getAge());
  ```

* 



## 19. await 表达式

* await右侧表达式`一般`为Promise对象，但也可以是其他的值

* 如果表达式是Promise对象，await返回的是`Promise成功的值`

* 如果表达式是其他的值，直接将此值作为await的返回值

  ```js
  1.
  const value = await Promise.resolve(1)
  console.log(value) // 1
  
  2.
  const reason = await Promise.reject(1)
  console.log(reason) // 报错 因为await返回的是`Promise成功的值` 失败就报错
  
  3.
  我们继续看下个例子
  function f1 () {
      const value = await Promise.resolve(2)
      console.log(value) 
  }
  f1()
  // 我们期待的结果是2 但是报错了 如果在函数中使用await 那么这个函数必须要是有async
  `Uncaught SyntaxError: await is only valid in async functions and the top level bodies of modules`
  
  4.
  async function f1 () {
      const value = await Promise.resolve(2)
      console.log(value)  // 2
  }
  f1()
  // 这回正确打印 老铁 没毛病！！！学废了么
  
  5.
  // 上面我们测试的await 后面都是Promise对象 假如张三这个同学调皮捣蛋，await后面就不跟个Promise对象，怎么办呢？打印的是什么呢？我们来看下
  async function f1 () {
      const value = await '法外狂徒张三'
      console.log(value)  // '法外狂徒张三'
  }
  f1()
  
  我们发现了如果表达式是其他的值，直接将此值作为await的返回值
  
  6. 进阶之路最后一步
  我们发现个问题，await返回是一个成功Promise的值 但是如果是失败Promise的呢我们该怎么获取到失败的值
  
  async function f1 () {
      try{
          const reason = await Promise.reject('失败了')
  	    console.log(reason)  // '法外狂徒张三'
      } catch (err) {
          console.log(err) // 失败了
      }
  }
  f1()
  ```

  

## 18. async与await语法糖

```js
1.
async function run() {}
console.log(run()); 
// 我们打印执行run方法其实是个Promise  
// 状态为已完成【resolved】

async function run() {
    return 1
}
run().then(res => console.log(res));

2.
async function run() {
    let res = await new Promise((resolve) => {
        resolve(1);
    }) // await就是then的语法糖 then(res => resolve(1))
    console.log(res);
}
run();

3.
async function run() {
    let res = await this.$api.scheduleDispatch.getPath()
    console.log(res);
}
run();
```

## 19. async错误处理

```js
1.在外面处理
async function run() {
    let res = await new Promise((resolve,reject) => {
        // resolve(1);
        reject(3);
    })
    return res;
}
run()
    .then(res=> console.log(res, 'res'))
    .catch(error => console.log(error, 'err'));

2. reject模拟网络请求出错（在内部处理）
async function run() {
    try {
        let res = await new Promise((resolve,reject) => {
            reject(3);
            return res;
    })
    } catch(err) {
        console.log(err);
    }
}
run()

3. 系统内部自动抛错
async function run() {
    try {
        let res = await new Promise((resolve,reject) => {
            console.log(a); // 打印一个未定义的变量 
            return res;
    })
    } catch(err) {
        console.log(err.message);
    }
}
run()
```





